<?xml version="1.0"?>
<robot xmlns:xacro="http://www.ros.org/wiki/xacro">

  <xacro:property name="joint_effort" value="56.0"/>
  <xacro:property name="joint_velocity" value="2.792527"/>
  <xacro:property name="joint_damping" value="0.0"/>
  <xacro:property name="joint_friction" value="0.0"/>

  <xacro:property name="gripper_link_mass" value="0.007"/>
  <xacro:property name="gripper_link_ixx" value="1e-6"/>
  <xacro:property name="gripper_link_iyy" value="1e-6"/>
  <xacro:property name="gripper_link_izz" value="1e-6"/>

  <xacro:macro name="gripper_link_inertial">
    <inertial>
      <origin xyz="0 0 0.0" rpy="0 0 0"/>
      <mass value="${gripper_link_mass}"/>
      <inertia
        ixx="${gripper_link_ixx}" ixy="0.0" ixz="0.0"
        iyy="${gripper_link_iyy}" iyz="0.0"
        izz="${gripper_link_izz}"/>
    </inertial>
  </xacro:macro>

  <xacro:macro name="adaptive_gripper" params="parent prefix *origin">

    <link name="${prefix}gripper_base">
      <inertial>
        <origin xyz="0 0 0.0" rpy="0 0 0"/>
        <mass value="0.07"/>
        <inertia
          ixx="0.000010725" ixy="0.0" ixz="0.0"
          iyy="0.000014392" iyz="0.0"
          izz="0.000018517"/>
      </inertial>
      <visual>
        <geometry>
          <mesh filename="file://$(find mycobot_description)/meshes/adaptive_gripper/visual/gripper_base.dae"/>
        </geometry>
        <origin xyz="0.0 0.0 -0.012" rpy="0 0 0"/>
      </visual>
      <collision>
        <geometry>
          <box size="0.065 0.025 0.025"/>
        </geometry>
        <origin xyz="0.0 0.0 0.0" rpy="0 0 0"/>
      </collision>
    </link>

    <joint name="${prefix}${parent}_to_${prefix}gripper_base" type="fixed">
      <parent link="${prefix}${parent}"/>
      <child link="${prefix}gripper_base"/>
      <xacro:insert_block name="origin"/>
    </joint>

    <link name="${prefix}gripper_left1">
      <xacro:gripper_link_inertial/>
      <visual>
        <geometry>
          <mesh filename="file://$(find mycobot_description)/meshes/adaptive_gripper/visual/gripper_left1.dae"/>
        </geometry>
        <origin xyz="0.039 -0.0133 -0.012" rpy="0 0 0"/>
      </visual>
      <collision>
        <geometry>
          <box size="0.013 0.02 0.015"/>
        </geometry>
        <origin xyz="0.013 0.042 -0.010" rpy="0 0 0"/>
      </collision>
    </link>

    <link name="${prefix}gripper_left2">
      <xacro:gripper_link_inertial/>
      <visual>
        <geometry>
          <mesh filename="file://$(find mycobot_description)/meshes/adaptive_gripper/visual/gripper_left2.dae"/>
        </geometry>
        <origin xyz="0.005 -0.0195 -0.012" rpy="0 0 0"/>
      </visual>
      <collision>
        <geometry>
          <box size="0.02 0.02 0.02"/>
        </geometry>
        <origin xyz="-0.025 0.0 -0.010" rpy="0 0 0"/>
      </collision>
    </link>

    <link name="${prefix}gripper_left3">
      <xacro:gripper_link_inertial/>
      <visual>
        <geometry>
          <mesh filename="file://$(find mycobot_description)/meshes/adaptive_gripper/visual/gripper_left3.dae"/>
        </geometry>
        <origin xyz="0.012 0.0025 -0.012" rpy="0 0 0"/>
      </visual>
      <collision>
        <geometry>
          <box size="0.01 0.01 0.01"/>
        </geometry>
        <origin xyz="-0.014 0.005 0.005" rpy="0 0 0"/>
      </collision>
    </link>

    <link name="${prefix}gripper_right1">
      <xacro:gripper_link_inertial/>
      <visual>
        <geometry>
          <mesh filename="file://$(find mycobot_description)/meshes/adaptive_gripper/visual/gripper_right1.dae"/>
        </geometry>
        <origin xyz="-0.039 -0.0133 -0.012" rpy="0 0 0"/>
      </visual>
      <collision>
        <geometry>
          <box size="0.013 0.02 0.015"/>
        </geometry>
        <origin xyz="-0.013 0.042 -0.010" rpy="0 0 0"/>
      </collision>
    </link>

    <link name="${prefix}gripper_right2">
      <xacro:gripper_link_inertial/>
      <visual>
        <geometry>
          <mesh filename="file://$(find mycobot_description)/meshes/adaptive_gripper/visual/gripper_right2.dae"/>
        </geometry>
        <origin xyz="-0.005 -0.0195 -0.012" rpy="0 0 0"/>
      </visual>
      <collision>
        <geometry>
          <box size="0.02 0.02 0.02"/>
        </geometry>
        <origin xyz="0.025 0.0 -0.010" rpy="0 0 0"/>
      </collision>
    </link>

    <link name="${prefix}gripper_right3">
      <xacro:gripper_link_inertial/>
      <visual>
        <geometry>
          <mesh filename="file://$(find mycobot_description)/meshes/adaptive_gripper/visual/gripper_right3.dae"/>
        </geometry>
        <origin xyz="-0.012 0.0025 -0.012" rpy="0 0 0"/>
      </visual>
      <collision>
        <geometry>
          <box size="0.01 0.01 0.01"/>
        </geometry>
        <origin xyz="0.014 0.005 0.005" rpy="0 0 0"/>
      </collision>
    </link>

    <joint name="${prefix}gripper_controller" type="revolute">
      <axis xyz="0 0 1"/>
      <limit effort="${joint_effort}" lower="-0.7" upper="0.15" velocity="${joint_velocity}"/>
      <parent link="${prefix}gripper_base"/>
      <child link="${prefix}gripper_left3"/>
      <origin xyz="-0.012 0.005 0" rpy="0 0 0"/>
      <dynamics damping="${joint_damping}" friction="${joint_friction}"/>
    </joint>

    <joint name="${prefix}gripper_base_to_${prefix}gripper_left2" type="revolute">
      <axis xyz="0 0 1"/>
      <limit effort="${joint_effort}" lower="-0.8" upper="0.5" velocity="${joint_velocity}"/>
      <parent link="${prefix}gripper_base"/>
      <child link="${prefix}gripper_left2"/>
      <origin xyz="-0.005 0.027 0" rpy="0 0 0"/>
      <mimic joint="${prefix}gripper_controller" multiplier="1.0" offset="0"/>
      <dynamics damping="${joint_damping}" friction="${joint_friction}"/>
    </joint>

    <joint name="${prefix}gripper_left3_to_${prefix}gripper_left1" type="revolute">
      <axis xyz="0 0 1"/>
      <limit effort="${joint_effort}" lower="-0.5" upper="0.5" velocity="${joint_velocity}"/>
      <parent link="${prefix}gripper_left3"/>
      <child link="${prefix}gripper_left1"/>
      <origin xyz="-0.027 0.016 0" rpy="0 0 0"/>
      <mimic joint="${prefix}gripper_controller" multiplier="-1.0" offset="0"/>
      <dynamics damping="${joint_damping}" friction="${joint_friction}"/>
    </joint>

    <joint name="${prefix}gripper_base_to_${prefix}gripper_right3" type="revolute">
      <axis xyz="0 0 1"/>
      <limit effort="${joint_effort}" lower="-0.15" upper="0.7" velocity="${joint_velocity}"/>
      <parent link="${prefix}gripper_base"/>
      <child link="${prefix}gripper_right3"/>
      <origin xyz="0.012 0.005 0" rpy="0 0 0"/>
      <mimic joint="${prefix}gripper_controller" multiplier="-1.0" offset="0"/>
      <dynamics damping="${joint_damping}" friction="${joint_friction}"/>
    </joint>

    <joint name="${prefix}gripper_base_to_${prefix}gripper_right2" type="revolute">
      <axis xyz="0 0 1"/>
      <limit effort="${joint_effort}" lower="-0.5" upper="0.8" velocity="${joint_velocity}"/>
      <parent link="${prefix}gripper_base"/>
      <child link="${prefix}gripper_right2"/>
      <origin xyz="0.005 0.027 0" rpy="0 0 0"/>
      <mimic joint="${prefix}gripper_controller" multiplier="-1.0" offset="0"/>
      <dynamics damping="${joint_damping}" friction="${joint_friction}"/>
    </joint>

    <joint name="${prefix}gripper_right3_to_${prefix}gripper_right1" type="revolute">
      <axis xyz="0 0 1"/>
      <limit effort="${joint_effort}" lower="-0.5" upper="0.5" velocity="${joint_velocity}"/>
      <parent link="${prefix}gripper_right3"/>
      <child link="${prefix}gripper_right1"/>
      <origin xyz="0.027 0.016 0" rpy="0 0 0"/>
      <mimic joint="${prefix}gripper_controller" multiplier="1.0" offset="0"/>
      <dynamics damping="${joint_damping}" friction="${joint_friction}"/>
    </joint>

    <gazebo reference="${prefix}gripper_base">
      <visual>
        <material>
          <ambient>1 1 1 1</ambient>
          <diffuse>1 1 1 1</diffuse>
          <specular>1 1 1 1</specular>
        </material>
      </visual>
    </gazebo>

  </xacro:macro>
</robot>